<?xml version="1.0" encoding="utf-8"?>
<robot xmlns:xacro="http://www.ros.org/wiki/xacro" name="hand">
  <!-- Gazebo adaptation: dynamics (dampening)-->
  <xacro:property name="joint_damping" value="1.0"/>
  <!-- END Gazebo adaptation-->

  <xacro:macro name="hand" params="description_pkg:='panda' connected_to:='' ns:='' rpy:='0 0 0' xyz:='0 0 0' ">
    <xacro:unless value="${connected_to == ''}">
      <joint name="${ns}_hand_joint" type="fixed">
        <parent link="${connected_to}"/>
        <child link="${ns}_hand"/>
        <origin xyz="${xyz}" rpy="${rpy}"/>
        <!-- Gazebo adaptation: dampening-->
        <dynamics damping="${joint_damping}"/>
        <!-- END Gazebo adaptation-->
      </joint>
    </xacro:unless>
    <link name="${ns}_hand">
      <visual>
        <geometry>
          <mesh filename="package://${description_pkg}/meshes/visual/hand.dae"/>
        </geometry>
      </visual>
      <collision>
        <geometry>
          <mesh filename="package://${description_pkg}/meshes/collision/hand.stl"/>
        </geometry>
      </collision>
      <!-- Gazebo adaptaion: ineria-->
      <inertial>
        <origin xyz="0 0 0" rpy="0 0 0" />
        <mass value="0.67893" />
        <inertia ixx="0.3" ixy="0.0" ixz="0.0" iyy="0.3" iyz="0.0" izz="0.3" />
      </inertial>
      <!-- END Gazebo adaptation-->
    </link>
    <link name="${ns}_leftfinger">
      <visual>
        <geometry>
          <mesh filename="package://${description_pkg}/meshes/visual/finger.dae"/>
        </geometry>
      </visual>
      <collision>
        <geometry>
          <mesh filename="package://${description_pkg}/meshes/collision/finger.stl"/>
        </geometry>
      </collision>
      <!-- Gazebo adaptaion: ineria-->
      <inertial>
        <origin xyz="0 0 0" rpy="0 0 0" />
        <mass value="0.01053" />
        <inertia ixx="0.3" ixy="0.0" ixz="0.0" iyy="0.3" iyz="0.0" izz="0.3" />
      </inertial>
      <!-- END Gazebo adaptation-->
    </link>
    <link name="${ns}_rightfinger">
      <visual>
        <origin xyz="0 0 0" rpy="0 0 ${pi}"/>
        <geometry>
          <mesh filename="package://${description_pkg}/meshes/visual/finger.dae"/>
        </geometry>
      </visual>
      <collision>
        <origin xyz="0 0 0" rpy="0 0 ${pi}"/>
        <geometry>
          <mesh filename="package://${description_pkg}/meshes/collision/finger.stl"/>
        </geometry>
      </collision>
      <!-- Gazebo adaptaion: ineria-->
      <inertial>
        <origin xyz="0 0 0" rpy="0 0 0" />
        <mass value="0.01053" />
        <inertia ixx="0.3" ixy="0.0" ixz="0.0" iyy="0.3" iyz="0.0" izz="0.3" />
      </inertial>
      <!-- END Gazebo adaptation-->
    </link>
    <joint name="${ns}_finger_joint1" type="prismatic">
      <parent link="${ns}_hand"/>
      <child link="${ns}_leftfinger"/>
      <origin xyz="0 0 0.0584" rpy="0 0 0"/>
      <axis xyz="0 1 0"/>
      <limit effort="20" lower="0.0" upper="0.04" velocity="0.2"/>
      <!-- Gazebo adaptation: dampening-->
      <dynamics damping="${joint_damping}"/>
      <!-- END Gazebo adaptation-->
    </joint>
    <joint name="${ns}_finger_joint2" type="prismatic">
      <parent link="${ns}_hand"/>
      <child link="${ns}_rightfinger"/>
      <origin xyz="0 0 0.0584" rpy="0 0 0"/>
      <axis xyz="0 -1 0"/>
      <limit effort="20" lower="0.0" upper="0.04" velocity="0.2"/>
      <mimic joint="${ns}_finger_joint1" />
      <!-- Gazebo adaptation: dampening-->
      <dynamics damping="${joint_damping}"/>
      <!-- END Gazebo adaptation-->
    </joint>
  </xacro:macro>
</robot>
